#usda 1.0
(
    customLayerData = {
        string creator = "URDF USD Converter v0.1.2"
    }
    defaultPrim = "zeko"
    doc = """Generated from Composed Stage of root layer /tmp/tmpk3wvdxt0/zeko.usdc


Generated from Composed Stage of root layer /tmp/urdf_import_zeko_0uaxugpy/usdex_zeko/zeko.usdc


Generated from Composed Stage of root layer /tmp/urdf_import_zeko_0uaxugpy/temp_zeko/zeko.usd


Generated from Composed Stage of root layer /home/zeko-sim/Downloads/zeko_description(2)/urdf/zeko/payloads/base.usd
"""
    kilogramsPerUnit = 1
    metersPerUnit = 1
    upAxis = "Z"
)

over "zeko"
{
    over "Geometry"
    {
        over "base_link" (
            prepend apiSchemas = ["PhysicsRigidBodyAPI", "PhysicsArticulationRootAPI", "NewtonArticulationRootAPI", "PhysicsMassAPI"]
        )
        {
            bool newton:selfCollisionEnabled = 0
            point3f physics:centerOfMass = (0, 0, 0.16215672)
            float3 physics:diagonalInertia = (0.73830724, 1.83627, 2.4707212)
            float physics:mass = 59.345375
            quatf physics:principalAxes = (1, 0, 0, 0)

            over "left_wheel_link" (
                prepend apiSchemas = ["PhysicsRigidBodyAPI", "PhysicsMassAPI"]
            )
            {
                point3f physics:centerOfMass = (0, 0, 0)
                float3 physics:diagonalInertia = (0.043166675, 0.0434079, 0.07991526)
                float physics:mass = 6.6379833
                quatf physics:principalAxes = (-0.70710677, 0.70710677, 0, 0)

                over "cylinder" (
                    prepend apiSchemas = ["NewtonCollisionAPI"]
                )
                {
                }
            }

            over "right_wheel_link" (
                prepend apiSchemas = ["PhysicsRigidBodyAPI", "PhysicsMassAPI"]
            )
            {
                point3f physics:centerOfMass = (0, 0, 0)
                float3 physics:diagonalInertia = (0.043166675, 0.0434079, 0.07991526)
                float physics:mass = 6.6379833
                quatf physics:principalAxes = (-0.70710677, 0.70710677, 0, 0)

                over "cylinder" (
                    prepend apiSchemas = ["NewtonCollisionAPI"]
                )
                {
                }
            }

            over "front_caster_link" (
                prepend apiSchemas = ["PhysicsRigidBodyAPI", "PhysicsMassAPI"]
            )
            {
                point3f physics:centerOfMass = (0, 0, 0)
                float3 physics:diagonalInertia = (0.000486, 0.000486, 0.000486)
                float physics:mass = 0.6
                quatf physics:principalAxes = (1, 0, 0, 0)

                over "sphere" (
                    prepend apiSchemas = ["NewtonCollisionAPI"]
                )
                {
                }
            }

            over "rear_caster_link" (
                prepend apiSchemas = ["PhysicsRigidBodyAPI", "PhysicsMassAPI"]
            )
            {
                point3f physics:centerOfMass = (0, 0, 0)
                float3 physics:diagonalInertia = (0.000486, 0.000486, 0.000486)
                float physics:mass = 0.6
                quatf physics:principalAxes = (1, 0, 0, 0)

                over "sphere" (
                    prepend apiSchemas = ["NewtonCollisionAPI"]
                )
                {
                }
            }

            over "support_frame_link" (
                prepend apiSchemas = ["PhysicsRigidBodyAPI", "PhysicsMassAPI"]
            )
            {
                point3f physics:centerOfMass = (0, 0, 0.1415)
                float3 physics:diagonalInertia = (0.04430796, 0.056270666, 0.05868129)
                float physics:mass = 3.5
                quatf physics:principalAxes = (-0.70710677, 0.70710677, 0, 0)

                over "pelvis_mount_link" (
                    prepend apiSchemas = ["PhysicsRigidBodyAPI", "PhysicsMassAPI"]
                )
                {
                    point3f physics:centerOfMass = (0, 0, 0.076)
                    float3 physics:diagonalInertia = (0.01843225, 0.02608225, 0.0329625)
                    float physics:mass = 3
                    quatf physics:principalAxes = (6.123234e-17, 0.70710677, 0.70710677, 0)

                    over "box" (
                        prepend apiSchemas = ["NewtonCollisionAPI"]
                    )
                    {
                    }
                }

                over "box" (
                    prepend apiSchemas = ["NewtonCollisionAPI"]
                )
                {
                }
            }

            over "box" (
                prepend apiSchemas = ["NewtonCollisionAPI"]
            )
            {
            }
        }
    }

    over "Physics"
    {
        def PhysicsRevoluteJoint "left_wheel_joint" (
            prepend apiSchemas = ["PhysicsDriveAPI:angular", "PhysicsJointStateAPI:angular"]
        )
        {
            float drive:angular:physics:damping = 0.1
            float drive:angular:physics:maxForce = 60
            uniform token physics:axis = "Y"
            custom rel physics:body0
            prepend rel physics:body0 = </zeko/Geometry/base_link>
            custom rel physics:body1
            prepend rel physics:body1 = </zeko/Geometry/base_link/left_wheel_link>
            point3f physics:localPos0 = (0, 0.3, 0.1524)
            point3f physics:localPos1 = (0, 0, 0)
            quatf physics:localRot0 = (1, 0, 0, 0)
            quatf physics:localRot1 = (1, 0, 0, 0)
            custom float urdf:dynamics:damping = 0.1
            custom float urdf:dynamics:friction = 0.05
            custom float urdf:limit:effort = 60
            custom float urdf:limit:velocity = 20
        }

        def PhysicsRevoluteJoint "right_wheel_joint" (
            prepend apiSchemas = ["PhysicsDriveAPI:angular", "PhysicsJointStateAPI:angular"]
        )
        {
            float drive:angular:physics:damping = 0.1
            float drive:angular:physics:maxForce = 60
            uniform token physics:axis = "Y"
            custom rel physics:body0
            prepend rel physics:body0 = </zeko/Geometry/base_link>
            custom rel physics:body1
            prepend rel physics:body1 = </zeko/Geometry/base_link/right_wheel_link>
            point3f physics:localPos0 = (0, -0.3, 0.1524)
            point3f physics:localPos1 = (0, 0, 0)
            quatf physics:localRot0 = (1, 0, 0, 0)
            quatf physics:localRot1 = (1, 0, 0, 0)
            custom float urdf:dynamics:damping = 0.1
            custom float urdf:dynamics:friction = 0.05
            custom float urdf:limit:effort = 60
            custom float urdf:limit:velocity = 20
        }

        def PhysicsFixedJoint "front_caster_joint"
        {
            custom rel physics:body0
            prepend rel physics:body0 = </zeko/Geometry/base_link>
            custom rel physics:body1
            prepend rel physics:body1 = </zeko/Geometry/base_link/front_caster_link>
            point3f physics:localPos0 = (0.45, 0, 0.045)
            point3f physics:localPos1 = (0, 0, 0)
            quatf physics:localRot0 = (1, 0, 0, 0)
            quatf physics:localRot1 = (1, 0, 0, 0)
        }

        def PhysicsFixedJoint "rear_caster_joint"
        {
            custom rel physics:body0
            prepend rel physics:body0 = </zeko/Geometry/base_link>
            custom rel physics:body1
            prepend rel physics:body1 = </zeko/Geometry/base_link/rear_caster_link>
            point3f physics:localPos0 = (-0.45, 0, 0.045)
            point3f physics:localPos1 = (0, 0, 0)
            quatf physics:localRot0 = (1, 0, 0, 0)
            quatf physics:localRot1 = (1, 0, 0, 0)
        }

        def PhysicsFixedJoint "support_frame_joint"
        {
            custom rel physics:body0
            prepend rel physics:body0 = </zeko/Geometry/base_link>
            custom rel physics:body1
            prepend rel physics:body1 = </zeko/Geometry/base_link/support_frame_link>
            point3f physics:localPos0 = (0, 0, 0.221)
            point3f physics:localPos1 = (0, 0, 0)
            quatf physics:localRot0 = (1, 0, 0, 0)
            quatf physics:localRot1 = (1, 0, 0, 0)
        }

        def PhysicsFixedJoint "pelvis_mount_joint"
        {
            custom rel physics:body0
            prepend rel physics:body0 = </zeko/Geometry/base_link/support_frame_link>
            custom rel physics:body1
            prepend rel physics:body1 = </zeko/Geometry/base_link/support_frame_link/pelvis_mount_link>
            point3f physics:localPos0 = (0, 0, 0.283)
            point3f physics:localPos1 = (0, 0, 0)
            quatf physics:localRot0 = (1, 0, 0, 0)
            quatf physics:localRot1 = (1, 0, 0, 0)
        }
    }
}

