<?xml version="1.0"?>
<!-- This file is auto-generated from urdf/zeko.xacro. Do not edit by hand. -->
<robot name="zeko">
  <material name="zeko_chassis_grey">
    <color rgba="0.30 0.30 0.32 1.0" />
  </material>
  <material name="zeko_wheel_black">
    <color rgba="0.05 0.05 0.05 1.0" />
  </material>
  <material name="zeko_caster_dark_grey">
    <color rgba="0.15 0.15 0.15 1.0" />
  </material>
  <material name="zeko_frame_silver">
    <color rgba="0.75 0.76 0.78 1.0" />
  </material>
  <material name="zeko_pelvis_blue">
    <color rgba="0.10 0.35 0.75 1.0" />
  </material>
  <link name="base_link">
    <visual>
      <origin xyz="0 0 0" rpy="0 0 -1.5707963267948966" />
      <geometry>
        <mesh filename="package://zeko_description/meshes/base_link.stl" scale="0.001 0.001 0.001" />
      </geometry>
      <material name="zeko_chassis_grey" />
    </visual>
    <collision>
      <origin xyz="0 0 0.159" rpy="0 0 0" />
      <geometry>
        <box size="1.0 0.65 0.124" />
      </geometry>
    </collision>
    <inertial>
      <origin xyz="0 0 0.16215671974457993" rpy="0 0 0" />
      <mass value="59.345373525167496" />
      <inertia ixx="0.7383072611464968" ixy="0.0" ixz="0.0" iyy="1.8362699999999998" iyz="0.0" izz="2.4707211592356684" />
    </inertial>
  </link>
  <link name="left_wheel_link">
    <visual>
      <origin xyz="0 -0.3 -0.1524" rpy="0 0 -1.5707963267948966" />
      <geometry>
        <mesh filename="package://zeko_description/meshes/left_wheel_link.stl" scale="0.001 0.001 0.001" />
      </geometry>
      <material name="zeko_wheel_black" />
    </visual>
    <collision>
      <origin xyz="0 0 0" rpy="1.5707963267948966 0 0" />
      <geometry>
        <cylinder radius="0.1524" length="0.08" />
      </geometry>
    </collision>
    <inertial>
      <origin xyz="0 0 0" rpy="0 0 0" />
      <mass value="6.637983487286445" />
      <inertia ixx="0.04316667515923567" ixy="0.0" ixz="0.0" iyy="0.07991526114649682" iyz="0.0" izz="0.04340789808917197" />
    </inertial>
  </link>
  <joint name="left_wheel_joint" type="continuous">
    <parent link="base_link" />
    <child link="left_wheel_link" />
    <origin xyz="0 0.3 0.1524" rpy="0 0 0" />
    <axis xyz="0 1 0" />
    <limit effort="60.0" velocity="20.0" />
    <dynamics damping="0.1" friction="0.05" />
  </joint>
  <link name="right_wheel_link">
    <visual>
      <origin xyz="0 0.3 -0.1524" rpy="0 0 -1.5707963267948966" />
      <geometry>
        <mesh filename="package://zeko_description/meshes/right_wheel_link.stl" scale="0.001 0.001 0.001" />
      </geometry>
      <material name="zeko_wheel_black" />
    </visual>
    <collision>
      <origin xyz="0 0 0" rpy="1.5707963267948966 0 0" />
      <geometry>
        <cylinder radius="0.1524" length="0.08" />
      </geometry>
    </collision>
    <inertial>
      <origin xyz="0 0 0" rpy="0 0 0" />
      <mass value="6.637983487286445" />
      <inertia ixx="0.04316667515923567" ixy="0.0" ixz="0.0" iyy="0.07991526114649682" iyz="0.0" izz="0.04340789808917197" />
    </inertial>
  </link>
  <joint name="right_wheel_joint" type="continuous">
    <parent link="base_link" />
    <child link="right_wheel_link" />
    <origin xyz="0 -0.3 0.1524" rpy="0 0 0" />
    <axis xyz="0 1 0" />
    <limit effort="60.0" velocity="20.0" />
    <dynamics damping="0.1" friction="0.05" />
  </joint>
  <link name="front_caster_link">
    <visual>
      <origin xyz="-0.45 0 -0.045" rpy="0 0 -1.5707963267948966" />
      <geometry>
        <mesh filename="package://zeko_description/meshes/front_caster_fork.stl" scale="0.001 0.001 0.001" />
      </geometry>
      <material name="zeko_caster_dark_grey" />
    </visual>
    <visual>
      <origin xyz="-0.45 0 -0.045" rpy="0 0 -1.5707963267948966" />
      <geometry>
        <mesh filename="package://zeko_description/meshes/front_caster_wheel.stl" scale="0.001 0.001 0.001" />
      </geometry>
      <material name="zeko_wheel_black" />
    </visual>
    <collision>
      <origin xyz="0 0 0" rpy="0 0 0" />
      <geometry>
        <sphere radius="0.045" />
      </geometry>
    </collision>
    <inertial>
      <origin xyz="0 0 0" rpy="0 0 0" />
      <mass value="0.6" />
      <inertia ixx="0.00048599999999999994" ixy="0.0" ixz="0.0" iyy="0.00048599999999999994" iyz="0.0" izz="0.00048599999999999994" />
    </inertial>
  </link>
  <joint name="front_caster_joint" type="fixed">
    <parent link="base_link" />
    <child link="front_caster_link" />
    <origin xyz="0.45 0 0.045" rpy="0 0 0" />
  </joint>
  <link name="rear_caster_link">
    <visual>
      <origin xyz="0.45 0 -0.045" rpy="0 0 -1.5707963267948966" />
      <geometry>
        <mesh filename="package://zeko_description/meshes/rear_caster_fork.stl" scale="0.001 0.001 0.001" />
      </geometry>
      <material name="zeko_caster_dark_grey" />
    </visual>
    <visual>
      <origin xyz="0.45 0 -0.045" rpy="0 0 -1.5707963267948966" />
      <geometry>
        <mesh filename="package://zeko_description/meshes/rear_caster_wheel.stl" scale="0.001 0.001 0.001" />
      </geometry>
      <material name="zeko_wheel_black" />
    </visual>
    <collision>
      <origin xyz="0 0 0" rpy="0 0 0" />
      <geometry>
        <sphere radius="0.045" />
      </geometry>
    </collision>
    <inertial>
      <origin xyz="0 0 0" rpy="0 0 0" />
      <mass value="0.6" />
      <inertia ixx="0.00048599999999999994" ixy="0.0" ixz="0.0" iyy="0.00048599999999999994" iyz="0.0" izz="0.00048599999999999994" />
    </inertial>
  </link>
  <joint name="rear_caster_joint" type="fixed">
    <parent link="base_link" />
    <child link="rear_caster_link" />
    <origin xyz="-0.45 0 0.045" rpy="0 0 0" />
  </joint>
  <link name="support_frame_link">
    <visual>
      <origin xyz="0 0 -0.221" rpy="0 0 -1.5707963267948966" />
      <geometry>
        <mesh filename="package://zeko_description/meshes/support_frame_link.stl" scale="0.001 0.001 0.001" />
      </geometry>
      <material name="zeko_frame_silver" />
    </visual>
    <collision>
      <origin xyz="0 0 0.1415" rpy="0 0 0" />
      <geometry>
        <box size="0.348 0.268 0.283" />
      </geometry>
    </collision>
    <inertial>
      <origin xyz="0 0 0.1415" rpy="0 0 0" />
      <mass value="3.5" />
      <inertia ixx="0.04430795833333333" ixy="0.0" ixz="0.0" iyy="0.05868129166666665" iyz="0.0" izz="0.056270666666666656" />
    </inertial>
  </link>
  <joint name="support_frame_joint" type="fixed">
    <parent link="base_link" />
    <child link="support_frame_link" />
    <origin xyz="0 0 0.221" rpy="0 0 0" />
  </joint>
  <link name="pelvis_mount_link">
    <visual>
      <origin xyz="0 0 -0.504" rpy="0 0 -1.5707963267948966" />
      <geometry>
        <mesh filename="package://zeko_description/meshes/pelvis_mount_link.stl" scale="0.001 0.001 0.001" />
      </geometry>
      <material name="zeko_pelvis_blue" />
    </visual>
    <collision>
      <origin xyz="0 0 0.076" rpy="0 0 0" />
      <geometry>
        <box size="0.225 0.285 0.152" />
      </geometry>
    </collision>
    <inertial>
      <origin xyz="0 0 0.076" rpy="0 0 0" />
      <mass value="3.0" />
      <inertia ixx="0.026082249999999998" ixy="0.0" ixz="0.0" iyy="0.01843225" iyz="0.0" izz="0.0329625" />
    </inertial>
  </link>
  <joint name="pelvis_mount_joint" type="fixed">
    <parent link="support_frame_link" />
    <child link="pelvis_mount_link" />
    <origin xyz="0 0 0.283" rpy="0 0 0" />
  </joint>
  <ros2_control name="zeko_system" type="system">
    <hardware>
      <plugin>mock_components/GenericSystem</plugin>
    </hardware>
    <joint name="left_wheel_joint">
      <command_interface name="velocity">
        <param name="min">-20.0</param>
        <param name="max">20.0</param>
      </command_interface>
      <state_interface name="position" />
      <state_interface name="velocity" />
    </joint>
    <joint name="right_wheel_joint">
      <command_interface name="velocity">
        <param name="min">-20.0</param>
        <param name="max">20.0</param>
      </command_interface>
      <state_interface name="position" />
      <state_interface name="velocity" />
    </joint>
  </ros2_control>
</robot>
